Workbook

Sheet cleaned_orders
A1: order_id | B1: order_date | C1: ship_date | D1: customer_id | E1: customer_name | F1: segment | G1: region | H1: state | I1: city | J1: category | K1: sub_category | L1: product_name | M1: ship_mode | N1: quantity | O1: unit_price | P1: discount | Q1: sales | R1: cost | S1: profit | T1: payment_status | U1: order_status | V1: Joint | W1: conflicting_duplicates | X1: exact_duplicate_rows | Y1: duplicate_order_id_flag | Z1: duplicate_review_flag | AA1: data_quality_flag | AB1: date_quality_flag | AC1: shipping_delay_days | AD1: shipping_date_issue | AE1: date_format_flag | AF1: flag_valid_order_date | AG1: flag_valid_shipping_date | AH1: flag_missing_order_date | AI1: flag_missing_shipping_date | AJ1: flag_missing_region | AK1: flag_missing_ship_mode | AL1: flag_missing_discount | AM1: flag_negative_discount | AN1: flag_discount_out_of_range | AO1: flag_invalid_shipping | AP1: any_rule_flag | AQ1: cleaned_discount | AR1: calculated_sales | AS1: sales difference | AT1: calculated_profit | AU1: profit diff | AV1: Profit_margin | AW1: Order Month | AX1: Order year
A2: ORD-2024-10001 | B2: 45494 | C2: 45500 | D2: CUST-4655 | E2: Karan Malhotra | F2: Consumer | G2: North | H2: Rajasthan | I2: Jaipur | J2: Office Supplies | K2: Paper | L2: Pro Paper 122 | M2: Second Class | N2: 8 | O2: 2976.45 | P2: 0.2 | Q2: 19049.28 | R2: 15841.89 | S2: 3207.39 | T2: Paid | U2: Completed | V2: =TEXTJOIN("|",TRUE,A2:U2) -> #NAME? | X2: =COUNTIF(V:V,V2)>1 -> TRUE | Y2: =IF(COUNTIF($A:$A,A2)>1,"Duplicate Order ID","Unique") -> Unique | Z2: =IF( COUNTIFS($A:$A,A2,$B:$B,B2)=COUNTIF($A:$A,A2), "Exact Duplicate", "Conflicting Duplicate" ) -> Exact Duplicate | AA2: =IF( OR(AQ2<0, AQ2>1, C2<B2), "Invalid", IF( OR(G2="Unknown", M2="Unknown"), "Warning", "Clean" ) ) -> Clean | AB2: =IF( OR( B2="", C2="", NOT(ISNUMBER(B2)), NOT(ISNUMBER(C2)), C2<B2 ), "Invalid", "Valid" ) -> Valid | AC2: 6 | AD2: =IF(C2<B2,"Invalid Shipping Date","Valid") -> Valid | AE2: =IF(AND(B2<>"",NOT(ISNUMBER(B2))),"Text Not Date","Valid") -> Valid | AF2: =IF(ISNUMBER(B2),"Valid","Invalid") -> Valid | AG2: =IF(ISNUMBER(C2),"Valid","Invalid") -> Valid | AH2: =IF(OR(B2="",ISBLANK(B2)),"Missing","Valid") -> Valid | AI2: =IF(OR(C2="",ISBLANK(C2)),"Missing","Valid") -> Valid | AJ2: FALSE | AK2: FALSE | AL2: FALSE | AM2: FALSE | AN2: FALSE | AO2: FALSE | AP2: FALSE | AQ2: =IF(OR(P2="",ISBLANK(P2)),0,P2) -> 0.2 | AR2: =N2*O2*(1-AQ2) -> 19049.28 | AS2: =Q2-AR2 -> 0 | AT2: =AR2-R2 -> 3207.39 | AU2: =S2-AT2 -> 0 | AV2: =AT2/AR2 -> 0.16837329 | AW2: =TEXT(B2,"mmmm") -> July | AX2: =YEAR(B2) -> 2024
A3: ORD-2024-10002 | B3: 45535 | C3: 45540 | D3: CUST-2054 | E3: Mira Das | F3: Small Business | G3: East | H3: Odisha | I3: Bhubaneswar | J3: Furniture | K3: Tables | L3: Pro Tables 258 | M3: Same Day | N3: 3 | O3: 2437.5 | P3: 0 | Q3: 7312.5 | R3: 4904.73 | S3: 2407.77 | T3: Paid | U3: Completed | V3: =TEXTJOIN("|",TRUE,A3:U3) -> #NAME? | X3: =COUNTIF(V:V,V3)>1 -> TRUE | Y3: =IF(COUNTIF($A:$A,A3)>1,"Duplicate Order ID","Unique") -> Unique | AA3: =IF( OR(AQ3<0, AQ3>1, C3<B3), "Invalid", IF( OR(G3="Unknown", M3="Unknown"), "Warning", "Clean" ) ) -> Clean | AB3: =IF( OR( B3="", C3="", NOT(ISNUMBER(B3)), NOT(ISNUMBER(C3)), C3<B3 ), "Invalid", "Valid" ) -> Valid | AC3: 5 | AD3: =IF(C3<B3,"Invalid Shipping Date","Valid") -> Valid | AE3: =IF(AND(B3<>"",NOT(ISNUMBER(B3))),"Text Not Date","Valid") -> Valid | AF3: =IF(ISNUMBER(B3),"Valid","Invalid") -> Valid | AG3: =IF(ISNUMBER(C3),"Valid","Invalid") -> Valid | AH3: =IF(OR(B3="",ISBLANK(B3)),"Missing","Valid") -> Valid | AI3: =IF(OR(C3="",ISBLANK(C3)),"Missing","Valid") -> Valid | AJ3: FALSE | AK3: FALSE | AL3: FALSE | AM3: FALSE | AN3: FALSE | AO3: FALSE | AP3: FALSE | AQ3: =IF(OR(P3="",ISBLANK(P3)),0,P3) -> 0 | AR3: =N3*O3*(1-AQ3) -> 7312.5 | AS3: =Q3-AR3 -> 0 | AT3: =AR3-R3 -> 2407.77 | AU3: =S3-AT3 -> 0 | AV3: =AT3/AR3 -> 0.32926769 | AW3: =TEXT(B3,"mmmm") -> August | AX3: =YEAR(B3) -> 2024
A4: ORD-2024-10003 | B4: 45451 | C4: 45458 | D4: CUST-6843 | E4: Isha Nair | F4: Consumer | G4: East | H4: Odisha | I4: Bhubaneswar | J4: Office Supplies | K4: Art | L4: Elite Art 525 | M4: First Class | N4: 4 | O4: 1065.43 | P4: 0.55 | Q4: 4261.72 | R4: 2465.69 | S4: 1796.03 | T4: Paid | U4: Completed | V4: =TEXTJOIN("|",TRUE,A4:U4) -> #NAME? | X4: =COUNTIF(V:V,V4)>1 -> TRUE | Y4: =IF(COUNTIF($A:$A,A4)>1,"Duplicate Order ID","Unique") -> Unique | AA4: =IF( OR(AQ4<0, AQ4>1, C4<B4), "Invalid", IF( OR(G4="Unknown", M4="Unknown"), "Warning", "Clean" ) ) -> Clean | AB4: =IF( OR( B4="", C4="", NOT(ISNUMBER(B4)), NOT(ISNUMBER(C4)), C4<B4 ), "Invalid", "Valid" ) -> Valid | AC4: 7 | AD4: =IF(C4<B4,"Invalid Shipping Date","Valid") -> Valid | AE4: =IF(AND(B4<>"",NOT(ISNUMBER(B4))),"Text Not Date","Valid") -> Valid | AF4: =IF(ISNUMBER(B4),"Valid","Invalid") -> Valid | AG4: =IF(ISNUMBER(C4),"Valid","Invalid") -> Valid | AH4: =IF(OR(B4="",ISBLANK(B4)),"Missing","Valid") -> Valid | AI4: =IF(OR(C4="",ISBLANK(C4)),"Missing","Valid") -> Valid | AJ4: FALSE | AK4: FALSE | AL4: FALSE | AM4: FALSE | AN4: FALSE | AO4: FALSE | AP4: FALSE | AQ4: =IF(OR(P4="",ISBLANK(P4)),0,P4) -> 0.55 | AR4: =N4*O4*(1-AQ4) -> 1917.774 | AS4: =Q4-AR4 -> 2343.946 | AT4: =AR4-R4 -> -547.916 | AU4: =S4-AT4 -> 2343.946 | AV4: =AT4/AR4 -> -0.28570415 | AW4: =TEXT(B4,"mmmm") -> June | AX4: =YEAR(B4) -> 2024
A5: ORD-2024-10004 | B5: 45624 | C5: 45625 | D5: CUST-3722 | E5: Arjun Bose | F5: Small Business | G5: South | H5: Telangana | I5: Hyderabad | J5: Furniture | K5: Furnishings | L5: Smart Furnishings 294 | M5: Standard Class | N5: 6 | O5: 1848.43 | P5: 0.25 | Q5: 8317.93 | R5: 6796.77 | S5: 1521.16 | T5: Paid | U5: Completed | V5: =TEXTJOIN("|",TRUE,A5:U5) -> #NAME? | X5: =COUNTIF(V:V,V5)>1 -> TRUE | Y5: =IF(COUNTIF($A:$A,A5)>1,"Duplicate Order ID","Unique") -> Unique | AA5: =IF( OR(AQ5<0, AQ5>1, C5<B5), "Invalid", IF( OR(G5="Unknown", M5="Unknown"), "Warning", "Clean" ) ) -> Clean | AB5: =IF( OR( B5="", C5="", NOT(ISNUMBER(B5)), NOT(ISNUMBER(C5)), C5<B5 ), "Invalid", "Valid" ) -> Valid | AC5: 1 | AD5: =IF(C5<B5,"Invalid Shipping Date","Valid") -> Valid | AE5: =IF(AND(B5<>"",NOT(ISNUMBER(B5))),"Text Not Date","Valid") -> Valid | AF5: =IF(ISNUMBER(B5),"Valid","Invalid") -> Valid | AG5: =IF(ISNUMBER(C5),"Valid","Invalid") -> Valid | AH5: =IF(OR(B5="",ISBLANK(B5)),"Missing","Valid") -> Valid | AI5: =IF(OR(C5="",ISBLANK(C5)),"Missing","Valid") -> Valid | AJ5: FALSE | AK5: FALSE | AL5: FALSE | AM5: FALSE | AN5: FALSE | AO5: FALSE | AP5: FALSE | AQ5: =IF(OR(P5="",ISBLANK(P5)),0,P5) -> 0.25 | AR5: =N5*O5*(1-AQ5) -> 8317.935 | AS5: =Q5-AR5 -> -0.005 | AT5: =AR5-R5 -> 1521.165 | AU5: =S5-AT5 -> -0.005 | AV5: =AT5/AR5 -> 0.18287772 | AW5: =TEXT(B5,"mmmm") -> November | AX5: =YEAR(B5) -> 2024
A6: ORD-2025-10005 | B6: 45898 | C6: 45901 | D6: CUST-8130 | E6: Ananya Rao | F6: Small Business | G6: West | H6: Maharashtra | I6: Mumbai | J6: Furniture | K6: Chairs | L6: Elite Chairs 543 | M6: First Class | N6: 7 | O6: 2973.76 | P6: 0 | Q6: 20816.32 | R6: 17705.37 | S6: 3110.95 | T6: Paid | U6: Cancelled | V6: =TEXTJOIN("|",TRUE,A6:U6) -> #NAME? | X6: =COUNTIF(V:V,V6)>1 -> TRUE | Y6: =IF(COUNTIF($A:$A,A6)>1,"Duplicate Order ID","Unique") -> Unique | AA6: =IF( OR(AQ6<0, AQ6>1, C6<B6), "Invalid", IF( OR(G6="Unknown", M6="Unknown"), "Warning", "Clean" ) ) -> Clean | AB6: =IF( OR( B6="", C6="", NOT(ISNUMBER(B6)), NOT(ISNUMBER(C6)), C6<B6 ), "Invalid", "Valid" ) -> Valid | AC6: 3 | AD6: =IF(C6<B6,"Invalid Shipping Date","Valid") -> Valid | AE6: =IF(AND(B6<>"",NOT(ISNUMBER(B6))),"Text Not Date","Valid") -> Valid | AF6: =IF(ISNUMBER(B6),"Valid","Invalid") -> Valid | AG6: =IF(ISNUMBER(C6),"Valid","Invalid") -> Valid | AH6: =IF(OR(B6="",ISBLANK(B6)),"Missing","Valid") -> Valid | AI6: =IF(OR(C6="",ISBLANK(C6)),"Missing","Valid") -> Valid | AJ6: FALSE | AK6: FALSE | AL6: FALSE | AM6: FALSE | AN6: FALSE | AO6: FALSE | AP6: FALSE | AQ6: =IF(OR(P6="",ISBLANK(P6)),0,P6) -> 0 | AR6: =N6*O6*(1-AQ6) -> 20816.32 | AS6: =Q6-AR6 -> 0 | AT6: =AR6-R6 -> 3110.95 | AU6: =S6-AT6 -> 0 | AV6: =AT6/AR6 -> 0.14944764 | AW6: =TEXT(B6,"mmmm") -> August | AX6: =YEAR(B6) -> 2025
A7: ORD-2024-10006 | B7: 45436 | C7: 45440 | D7: CUST-6056 | E7: Vikram Iyer | F7: Small Business | G7: West | H7: Madhya Pradesh | I7: Indore | J7: Technology | K7: Accessories | L7: Pro Accessories 821 | M7: Same Day | N7: 3 | O7: 1053.11 | P7: 0.2 | Q7: 2527.46 | R7: 1533.58 | S7: 993.88 | T7: Paid | U7: Completed | V7: =TEXTJOIN("|",TRUE,A7:U7) -> #NAME? | X7: =COUNTIF(V:V,V7)>1 -> TRUE | Y7: =IF(COUNTIF($A:$A,A7)>1,"Duplicate Order ID","Unique") -> Unique | AA7: =IF( OR(AQ7<0, AQ7>1, C7<B7), "Invalid", IF( OR(G7="Unknown", M7="Unknown"), "Warning", "Clean" ) ) -> Clean | AB7: =IF( OR( B7="", C7="", NOT(ISNUMBER(B7)), NOT(ISNUMBER(C7)), C7<B7 ), "Invalid", "Valid" ) -> Valid | AC7: 4 | AD7: =IF(C7<B7,"Invalid Shipping Date","Valid") -> Valid | AE7: =IF(AND(B7<>"",NOT(ISNUMBER(B7))),"Text Not Date","Valid") -> Valid | AF7: =IF(ISNUMBER(B7),"Valid","Invalid") -> Valid | AG7: =IF(ISNUMBER(C7),"Valid","Invalid") -> Valid | AH7: =IF(OR(B7="",ISBLANK(B7)),"Missing","Valid") -> Valid | AI7: =IF(OR(C7="",ISBLANK(C7)),"Missing","Valid") -> Valid | AJ7: FALSE | AK7: FALSE | AL7: FALSE | AM7: FALSE | AN7: FALSE | AO7: FALSE | AP7: FALSE | AQ7: =IF(OR(P7="",ISBLANK(P7)),0,P7) -> 0.2 | AR7: =N7*O7*(1-AQ7) -> 2527.464 | AS7: =Q7-AR7 -> -0.004 | AT7: =AR7-R7 -> 993.884 | AU7: =S7-AT7 -> -0.004 | AV7: =AT7/AR7 -> 0.39323369 | AW7: =TEXT(B7,"mmmm") -> May | AX7: =YEAR(B7) -> 2024
A8: ORD-2025-10007 | B8: 45757 | C8: 45763 | D8: CUST-3656 | E8: Neha Gupta | F8: Consumer | G8: East | H8: Odisha | I8: Bhubaneswar | J8: Technology | K8: Copiers | L8: Eco Copiers 790 | M8: Standard Class | N8: 4 | O8: 1719.87 | P8: 0.15 | Q8: 5847.56 | R8: 4727.25 | S8: 1120.31 | T8: Paid | U8: Completed | V8: =TEXTJOIN("|",TRUE,A8:U8) -> #NAME? | W8: =IFERROR(__xludf.DUMMYFUNCTION("IF(COUNTIF($A:$A,A2)=1, ""Unique"", IF(COUNTUNIQUE(FILTER($V$2:$V$934,$A$2:$A$934=A2))>1, ""Conflicting Duplicate"", ""Exact Duplicate""))"),"Unique") -> Unique | X8: =COUNTIF(V:V,V8)>1 -> TRUE | Y8: =IF(COUNTIF($A:$A,A8)>1,"Duplicate Order ID","Unique") -> Duplicate Order ID | AA8: =IF( OR(AQ8<0, AQ8>1, C8<B8), "Invalid", IF( OR(G8="Unknown", M8="Unknown"), "Warning", "Clean" ) ) -> Clean | AB8: =IF( OR( B8="", C8="", NOT(ISNUMBER(B8)), NOT(ISNUMBER(C8)), C8<B8 ), "Invalid", "Valid" ) -> Valid | AC8: 6 | AD8: =IF(C8<B8,"Invalid Shipping Date","Valid") -> Valid | AE8: =IF(AND(B8<>"",NOT(ISNUMBER(B8))),"Text Not Date","Valid") -> Valid | AF8: =IF(ISNUMBER(B8),"Valid","Invalid") -> Valid | AG8: =IF(ISNUMBER(C8),"Valid","Invalid") -> Valid | AH8: =IF(OR(B8="",ISBLANK(B8)),"Missing","Valid") -> Valid | AI8: =IF(OR(C8="",ISBLANK(C8)),"Missing","Valid") -> Valid | AJ8: FALSE | AK8: FALSE | AL8: FALSE | AM8: FALSE | AN8: FALSE | AO8: FALSE | AP8: FALSE | AQ8: =IF(OR(P8="",ISBLANK(P8)),0,P8) -> 0.15 | AR8: =N8*O8*(1-AQ8) -> 5847.558 | AS8: =Q8-AR8 -> 0.002 | AT8: =AR8-R8 -> 1120.308 | AU8: =S8-AT8 -> 0.002 | AV8: =AT8/AR8 -> 0.19158562 | AW8: =TEXT(B8,"mmmm") -> April | AX8: =YEAR(B8) -> 2025
A9: ORD-2025-10008 | B9: 45711 | C9: 45714 | D9: CUST-4683 | E9: Isha Nair | F9: Small Business | G9: South | H9: Andhra Pradesh | I9: Vijayawada | J9: Office Supplies | K9: Art | L9: Eco Art 848 | M9: First Class | N9: 1 | O9: 2980.71 | P9: 0 | Q9: 2980.71 | R9: 2357.22 | S9: 623.49 | T9: Paid | U9: Completed | V9: =TEXTJOIN("|",TRUE,A9:U9) -> #NAME? | W9: =IFERROR(__xludf.DUMMYFUNCTION("IF(COUNTIF($A:$A,A3)=1, ""Unique"", IF(COUNTUNIQUE(FILTER($V$2:$V$934,$A$2:$A$934=A3))>1, ""Conflicting Duplicate"", ""Exact Duplicate""))"),"Unique") -> Unique | X9: =COUNTIF(V:V,V9)>1 -> TRUE | Y9: =IF(COUNTIF($A:$A,A9)>1,"Duplicate Order ID","Unique") -> Unique | AA9: =IF( OR(AQ9<0, AQ9>1, C9<B9), "Invalid", IF( OR(G9="Unknown", M9="Unknown"), "Warning", "Clean" ) ) -> Clean | AB9: =IF( OR( B9="", C9="", NOT(ISNUMBER(B9)), NOT(ISNUMBER(C9)), C9<B9 ), "Invalid", "Valid" ) -> Valid | AC9: 3 | AD9: =IF(C9<B9,"Invalid Shipping Date","Valid") -> Valid | AE9: =IF(AND(B9<>"",NOT(ISNUMBER(B9))),"Text Not Date","Valid") -> Valid | AF9: =IF(ISNUMBER(B9),"Valid","Invalid") -> Valid | AG9: =IF(ISNUMBER(C9),"Valid","Invalid") -> Valid | AH9: =IF(OR(B9="",ISBLANK(B9)),"Missing","Valid") -> Valid | AI9: =IF(OR(C9="",ISBLANK(C9)),"Missing","Valid") -> Valid | AJ9: FALSE | AK9: FALSE | AL9: FALSE | AM9: FALSE | AN9: FALSE | AO9: FALSE | AP9: FALSE | AQ9: =IF(OR(P9="",ISBLANK(P9)),0,P9) -> 0 | AR9: =N9*O9*(1-AQ9) -> 2980.71 | AS9: =Q9-AR9 -> 0 | AT9: =AR9-R9 -> 623.49 | AU9: =S9-AT9 -> 0 | AV9: =AT9/AR9 -> 0.209175 | AW9: =TEXT(B9,"mmmm") -> February | AX9: =YEAR(B9) -> 2025
A10: ORD-2024-10009 | B10: 45601 | C10: 45606 | D10: CUST-2598 | E10: Aditi Sen | F10: Corporate | G10: South | H10: Telangana | I10: Hyderabad | J10: Office Supplies | K10: Labels | L10: Classic Labels 815 | M10: First Class | N10: 8 | O10: 3134.2 | P10: 0 | Q10: 25073.6 | R10: 17347.23 | S10: 7726.37 | T10: Paid | U10: Completed | V10: =TEXTJOIN("|",TRUE,A10:U10) -> #NAME? | W10: =IFERROR(__xludf.DUMMYFUNCTION("IF(COUNTIF($A:$A,A4)=1, ""Unique"", IF(COUNTUNIQUE(FILTER($V$2:$V$934,$A$2:$A$934=A4))>1, ""Conflicting Duplicate"", ""Exact Duplicate""))"),"Unique") -> Unique | X10: =COUNTIF(V:V,V10)>1 -> TRUE | Y10: =IF(COUNTIF($A:$A,A10)>1,"Duplicate Order ID","Unique") -> Unique | AA10: =IF( OR(AQ10<0, AQ10>1, C10<B10), "Invalid", IF( OR(G10="Unknown", M10="Unknown"), "Warning", "Clean" ) ) -> Clean | AB10: =IF( OR( B10="", C10="", NOT(ISNUMBER(B10)), NOT(ISNUMBER(C10)), C10<B10 ), "Invalid", "Valid" ) -> Valid | AC10: 5 | AD10: =IF(C10<B10,"Invalid Shipping Date","Valid") -> Valid | AE10: =IF(AND(B10<>"",NOT(ISNUMBER(B10))),"Text Not Date","Valid") -> Valid | AF10: =IF(ISNUMBER(B10),"Valid","Invalid") -> Valid | AG10: =IF(ISNUMBER(C10),"Valid","Invalid") -> Valid | AH10: =IF(OR(B10="",ISBLANK(B10)),"Missing","Valid") -> Valid | AI10: =IF(OR(C10="",ISBLANK(C10)),"Missing","Valid") -> Valid | AJ10: FALSE | AK10: FALSE | AL10: FALSE | AM10: FALSE | AN10: FALSE | AO10: FALSE | AP10: FALSE | AQ10: =IF(OR(P10="",ISBLANK(P10)),0,P10) -> 0 | AR10: =N10*O10*(1-AQ10) -> 25073.6 | AS10: =Q10-AR10 -> 0 | AT10: =AR10-R10 -> 7726.37 | AU10: =S10-AT10 -> 0 | AV10: =AT10/AR10 -> 0.30814761 | AW10: =TEXT(B10,"mmmm") -> November | AX10: =YEAR(B10) -> 2024
A11: ORD-2025-10010 | B11: 45907 | C11: 45912 | D11: CUST-2483 | E11: Mira Das | F11: Home Office | G11: South | H11: Telangana | I11: Hyderabad | J11: Office Supplies | K11: Paper | L11: Pro Paper 622 | M11: Second Class | N11: 9 | O11: 852.04 | P11: 0.2 | Q11: 6134.69 | R11: 3800.19 | S11: 2334.5 | T11: Paid | U11: Completed | V11: =TEXTJOIN("|",TRUE,A11:U11) -> #NAME? | W11: =IFERROR(__xludf.DUMMYFUNCTION("IF(COUNTIF($A:$A,A5)=1, ""Unique"", IF(COUNTUNIQUE(FILTER($V$2:$V$934,$A$2:$A$934=A5))>1, ""Conflicting Duplicate"", ""Exact Duplicate""))"),"Unique") -> Unique | X11: =COUNTIF(V:V,V11)>1 -> TRUE | Y11: =IF(COUNTIF($A:$A,A11)>1,"Duplicate Order ID","Unique") -> Unique | AA11: =IF( OR(AQ11<0, AQ11>1, C11<B11), "Invalid", IF( OR(G11="Unknown", M11="Unknown"), "Warning", "Clean" ) ) -> Clean | AB11: =IF( OR( B11="", C11="", NOT(ISNUMBER(B11)), NOT(ISNUMBER(C11)), C11<B11 ), "Invalid", "Valid" ) -> Valid | AC11: 5 | AD11: =IF(C11<B11,"Invalid Shipping Date","Valid") -> Valid | AE11: =IF(AND(B11<>"",NOT(ISNUMBER(B11))),"Text Not Date","Valid") -> Valid | AF11: =IF(ISNUMBER(B11),"Valid","Invalid") -> Valid | AG11: =IF(ISNUMBER(C11),"Valid","Invalid") -> Valid | AH11: =IF(OR(B11="",ISBLANK(B11)),"Missing","Valid") -> Valid | AI11: =IF(OR(C11="",ISBLANK(C11)),"Missing","Valid") -> Valid | AJ11: FALSE | AK11: FALSE | AL11: FALSE | AM11: FALSE | AN11: FALSE | AO11: FALSE | AP11: FALSE | AQ11: =IF(OR(P11="",ISBLANK(P11)),0,P11) -> 0.2 | AR11: =N11*O11*(1-AQ11) -> 6134.688 | AS11: =Q11-AR11 -> 0.002 | AT11: =AR11-R11 -> 2334.498 | AU11: =S11-AT11 -> 0.002 | AV11: =AT11/AR11 -> 0.38054062 | AW11: =TEXT(B11,"mmmm") -> September | AX11: =YEAR(B11) -> 2025
A12: ORD-2025-10011 | B12: 45797 | C12: 45797 | D12: CUST-8092 | E12: Ananya Rao | F12: Corporate | G12: East | H12: West Bengal | I12: Kolkata | J12: Office Supplies | K12: Labels | L12: Prime Labels 644 | M12: Second Class | N12: 3 | O12: 3534.83 | P12: 0.05 | Q12: 10074.27 | R12: 6048.27 | S12: 4026 | T12: Refunded | U12: Returned | V12: =TEXTJOIN("|",TRUE,A12:U12) -> #NAME? | W12: =IFERROR(__xludf.DUMMYFUNCTION("IF(COUNTIF($A:$A,A6)=1, ""Unique"", IF(COUNTUNIQUE(FILTER($V$2:$V$934,$A$2:$A$934=A6))>1, ""Conflicting Duplicate"", ""Exact Duplicate""))"),"Unique") -> Unique | X12: =COUNTIF(V:V,V12)>1 -> TRUE | Y12: =IF(COUNTIF($A:$A,A12)>1,"Duplicate Order ID","Unique") -> Unique | AA12: =IF( OR(AQ12<0, AQ12>1, C12<B12), "Invalid", IF( OR(G12="Unknown", M12="Unknown"), "Warning", "Clean" ) ) -> Clean | AB12: =IF( OR( B12="", C12="", NOT(ISNUMBER(B12)), NOT(ISNUMBER(C12)), C12<B12 ), "Invalid", "Valid" ) -> Valid | AC12: 0 | AD12: =IF(C12<B12,"Invalid Shipping Date","Valid") -> Valid | AE12: =IF(AND(B12<>"",NOT(ISNUMBER(B12))),"Text Not Date","Valid") -> Valid | AF12: =IF(ISNUMBER(B12),"Valid","Invalid") -> Valid | AG12: =IF(ISNUMBER(C12),"Valid","Invalid") -> Valid | AH12: =IF(OR(B12="",ISBLANK(B12)),"Missing","Valid") -> Valid | AI12: =IF(OR(C12="",ISBLANK(C12)),"Missing","Valid") -> Valid | AJ12: FALSE | AK12: FALSE | AL12: FALSE | AM12: FALSE | AN12: FALSE | AO12: FALSE | AP12: FALSE | AQ12: =IF(OR(P12="",ISBLANK(P12)),0,P12) -> 0.05 | AR12: =N12*O12*(1-AQ12) -> 10074.265 | AS12: =Q12-AR12 -> 0.0045 | AT12: =AR12-R12 -> 4025.9955 | AU12: =S12-AT12 -> 0.0045 | AV12: =AT12/AR12 -> 0.39963167 | AW12: =TEXT(B12,"mmmm") -> May | AX12: =YEAR(B12) -> 2025
A13: ORD-2024-10012 | B13: 45495 | C13: 45496 | D13: CUST-6528 | E13: Vikram Iyer | F13: Small Business | G13: East | H13: Odisha | I13: Bhubaneswar | J13: Technology | K13: Accessories | L13: Smart Accessories 603 | M13: Same Day | N13: 6 | O13: 2005.95 | P13: 0.2 | Q13: 9628.56 | R13: 8038.59 | S13: 1589.97 | T13: Paid | U13: Completed | V13: =TEXTJOIN("|",TRUE,A13:U13) -> #NAME? | W13: =IFERROR(__xludf.DUMMYFUNCTION("IF(COUNTIF($A:$A,A7)=1, ""Unique"", IF(COUNTUNIQUE(FILTER($V$2:$V$934,$A$2:$A$934=A7))>1, ""Conflicting Duplicate"", ""Exact Duplicate""))"),"Unique") -> Unique | X13: =COUNTIF(V:V,V13)>1 -> TRUE | Y13: =IF(COUNTIF($A:$A,A13)>1,"Duplicate Order ID","Unique") -> Unique | AA13: =IF( OR(AQ13<0, AQ13>1, C13<B13), "Invalid", IF( OR(G13="Unknown", M13="Unknown"), "Warning", "Clean" ) ) -> Clean | AB13: =IF( OR( B13="", C13="", NOT(ISNUMBER(B13)), NOT(ISNUMBER(C13)), C13<B13 ), "Invalid", "Valid" ) -> Valid | AC13: 1 | AD13: =IF(C13<B13,"Invalid Shipping Date","Valid") -> Valid | AE13: =IF(AND(B13<>"",NOT(ISNUMBER(B13))),"Text Not Date","Valid") -> Valid | AF13: =IF(ISNUMBER(B13),"Valid","Invalid") -> Valid | AG13: =IF(ISNUMBER(C13),"Valid","Invalid") -> Valid | AH13: =IF(OR(B13="",ISBLANK(B13)),"Missing","Valid") -> Valid | AI13: =IF(OR(C13="",ISBLANK(C13)),"Missing","Valid") -> Valid | AJ13: FALSE | AK13: FALSE | AL13: FALSE | AM13: FALSE | AN13: FALSE | AO13: FALSE | AP13: FALSE | AQ13: =IF(OR(P13="",ISBLANK(P13)),0,P13) -> 0.2 | AR13: =N13*O13*(1-AQ13) -> 9628.56 | AS13: =Q13-AR13 -> 0 | AT13: =AR13-R13 -> 1589.97 | AU13: =S13-AT13 -> 0 | AV13: =AT13/AR13 -> 0.16513061 | AW13: =TEXT(B13,"mmmm") -> July | AX13: =YEAR(B13) -> 2024
A14: ORD-2024-10013 | B14: 45646 | C14: 45647 | D14: CUST-2648 | E14: Ananya Rao | F14: Corporate | G14: West | H14: Rajasthan | I14: Udaipur | J14: Office Supplies | K14: Paper | L14: Pro Paper 481 | M14: First Class | N14: 1 | O14: 702.14 | P14: 0.15 | Q14: 596.82 | R14: 380.25 | S14: 216.57 | T14: Pending | U14: Returned | V14: =TEXTJOIN("|",TRUE,A14:U14) -> #NAME? | W14: =IFERROR(__xludf.DUMMYFUNCTION("IF(COUNTIF($A:$A,A8)=1, ""Unique"", IF(COUNTUNIQUE(FILTER($V$2:$V$934,$A$2:$A$934=A8))>1, ""Conflicting Duplicate"", ""Exact Duplicate""))"),"Exact Duplicate") -> Exact Duplicate | X14: =COUNTIF(V:V,V14)>1 -> TRUE | Y14: =IF(COUNTIF($A:$A,A14)>1,"Duplicate Order ID","Unique") -> Unique | AA14: =IF( OR(AQ14<0, AQ14>1, C14<B14), "Invalid", IF( OR(G14="Unknown", M14="Unknown"), "Warning", "Clean" ) ) -> Clean | AB14: =IF( OR( B14="", C14="", NOT(ISNUMBER(B14)), NOT(ISNUMBER(C14)), C14<B14 ), "Invalid", "Valid" ) -> Valid | AC14: 1 | AD14: =IF(C14<B14,"Invalid Shipping Date","Valid") -> Valid | AE14: =IF(AND(B14<>"",NOT(ISNUMBER(B14))),"Text Not Date","Valid") -> Valid | AF14: =IF(ISNUMBER(B14),"Valid","Invalid") -> Valid | AG14: =IF(ISNUMBER(C14),"Valid","Invalid") -> Valid | AH14: =IF(OR(B14="",ISBLANK(B14)),"Missing","Valid") -> Valid | AI14: =IF(OR(C14="",ISBLANK(C14)),"Missing","Valid") -> Valid | AJ14: FALSE | AK14: FALSE | AL14: FALSE | AM14: FALSE | AN14: FALSE | AO14: FALSE | AP14: FALSE | AQ14: =IF(OR(P14="",ISBLANK(P14)),0,P14) -> 0.15 | AR14: =N14*O14*(1-AQ14) -> 596.819 | AS14: =Q14-AR14 -> 0.001 | AT14: =AR14-R14 -> 216.569 | AU14: =S14-AT14 -> 0.001 | AV14: =AT14/AR14 -> 0.36287216 | AW14: =TEXT(B14,"mmmm") -> December | AX14: =YEAR(B14) -> 2024
A15: ORD-2025-10014 | B15: 45942 | C15: 45946 | D15: CUST-7482 | E15: Priya Menon | F15: Small Business | G15: West | H15: Maharashtra | I15: Mumbai | J15: Office Supplies | K15: Art | L15: Smart Art 795 | M15: Second Class | N15: 7 | O15: 3964.72 | P15: 0.05 | Q15: 26365.39 | R15: 22306.24 | S15: 4059.15 | T15: Paid | U15: Completed | V15: =TEXTJOIN("|",TRUE,A15:U15) -> #NAME? | W15: =IFERROR(__xludf.DUMMYFUNCTION("IF(COUNTIF($A:$A,A9)=1, ""Unique"", IF(COUNTUNIQUE(FILTER($V$2:$V$934,$A$2:$A$934=A9))>1, ""Conflicting Duplicate"", ""Exact Duplicate""))"),"Unique") -> Unique | X15: =COUNTIF(V:V,V15)>1 -> TRUE | Y15: =IF(COUNTIF($A:$A,A15)>1,"Duplicate Order ID","Unique") -> Unique | AA15: =IF( OR(AQ15<0, AQ15>1, C15<B15), "Invalid", IF( OR(G15="Unknown", M15="Unknown"), "Warning", "Clean" ) ) -> Clean | AB15: =IF( OR( B15="", C15="", NOT(ISNUMBER(B15)), NOT(ISNUMBER(C15)), C15<B15 ), "Invalid", "Valid" ) -> Valid | AC15: 4 | AD15: =IF(C15<B15,"Invalid Shipping Date","Valid") -> Valid | AE15: =IF(AND(B15<>"",NOT(ISNUMBER(B15))),"Text Not Date","Valid") -> Valid | AF15: =IF(ISNUMBER(B15),"Valid","Invalid") -> Valid | AG15: =IF(ISNUMBER(C15),"Valid","Invalid") -> Valid | AH15: =IF(OR(B15="",ISBLANK(B15)),"Missing","Valid") -> Valid | AI15: =IF(OR(C15="",ISBLANK(C15)),"Missing","Valid") -> Valid | AJ15: FALSE | AK15: FALSE | AL15: FALSE | AM15: FALSE | AN15: FALSE | AO15: FALSE | AP15: FALSE | AQ15: =IF(OR(P15="",ISBLANK(P15)),0,P15) -> 0.05 | AR15: =N15*O15*(1-AQ15) -> 26365.388 | AS15: =Q15-AR15 -> 0.002 | AT15: =AR15-R15 -> 4059.148 | AU15: =S15-AT15 -> 0.002 | AV15: =AT15/AR15 -> 0.15395745 | AW15: =TEXT(B15,"mmmm") -> October | AX15: =YEAR(B15) -> 2025
A16: ORD-2024-10015 | B16: 45653 | C16: 45654 | D16: CUST-4912 | E16: Rahul Verma | F16: Consumer | G16: West | H16: Rajasthan | I16: Udaipur | J16: Technology | K16: Copiers | L16: Max Copiers 983 | M16: Standard Class | N16: 2 | O16: 2737.83 | P16: 0.25 | Q16: 4106.74 | R16: 2666.3 | S16: 1440.44 | T16: Paid | U16: Completed | V16: =TEXTJOIN("|",TRUE,A16:U16) -> #NAME? | W16: =IFERROR(__xludf.DUMMYFUNCTION("IF(COUNTIF($A:$A,A10)=1, ""Unique"", IF(COUNTUNIQUE(FILTER($V$2:$V$934,$A$2:$A$934=A10))>1, ""Conflicting Duplicate"", ""Exact Duplicate""))"),"Unique") -> Unique | X16: =COUNTIF(V:V,V16)>1 -> TRUE | Y16: =IF(COUNTIF($A:$A,A16)>1,"Duplicate Order ID","Unique") -> Unique | AA16: =IF( OR(AQ16<0, AQ16>1, C16<B16), "Invalid", IF( OR(G16="Unknown", M16="Unknown"), "Warning", "Clean" ) ) -> Clean | AB16: =IF( OR( B16="", C16="", NOT(ISNUMBER(B16)), NOT(ISNUMBER(C16)), C16<B16 ), "Invalid", "Valid" ) -> Valid | AC16: 1 | AD16: =IF(C16<B16,"Invalid Shipping Date","Valid") -> Valid | AE16: =IF(AND(B16<>"",NOT(ISNUMBER(B16))),"Text Not Date","Valid") -> Valid | AF16: =IF(ISNUMBER(B16),"Valid","Invalid") -> Valid | AG16: =IF(ISNUMBER(C16),"Valid","Invalid") -> Valid | AH16: =IF(OR(B16="",ISBLANK(B16)),"Missing","Valid") -> Valid | AI16: =IF(OR(C16="",ISBLANK(C16)),"Missing","Valid") -> Valid | AJ16: FALSE | AK16: FALSE | AL16: FALSE | AM16: FALSE | AN16: FALSE | AO16: FALSE | AP16: FALSE | AQ16: =IF(OR(P16="",ISBLANK(P16)),0,P16) -> 0.25 | AR16: =N16*O16*(1-AQ16) -> 4106.745 | AS16: =Q16-AR16 -> -0.005 | AT16: =AR16-R16 -> 1440.445 | AU16: =S16-AT16 -> -0.005 | AV16: =AT16/AR16 -> 0.35075102 | AW16: =TEXT(B16,"mmmm") -> December | AX16: =YEAR(B16) -> 2024
A17: ORD-2024-10016 | B17: 45482 | C17: 45482 | D17: CUST-7656 | E17: Karan Malhotra | F17: Small Business | G17: North | H17: Punjab | I17: Ludhiana | J17: Office Supplies | K17: Storage | L17: Classic Storage 198 | M17: Second Class | N17: 6 | O17: 3965.76 | P17: 0 | Q17: 23794.56 | R17: 15698.47 | S17: 8096.09 | T17: Paid | U17: Completed | V17: =TEXTJOIN("|",TRUE,A17:U17) -> #NAME? | W17: =IFERROR(__xludf.DUMMYFUNCTION("IF(COUNTIF($A:$A,A11)=1, ""Unique"", IF(COUNTUNIQUE(FILTER($V$2:$V$934,$A$2:$A$934=A11))>1, ""Conflicting Duplicate"", ""Exact Duplicate""))"),"Unique") -> Unique | X17: =COUNTIF(V:V,V17)>1 -> TRUE | Y17: =IF(COUNTIF($A:$A,A17)>1,"Duplicate Order ID","Unique") -> Unique | AA17: =IF( OR(AQ17<0, AQ17>1, C17<B17), "Invalid", IF( OR(G17="Unknown", M17="Unknown"), "Warning", "Clean" ) ) -> Clean | AB17: =IF( OR( B17="", C17="", NOT(ISNUMBER(B17)), NOT(ISNUMBER(C17)), C17<B17 ), "Invalid", "Valid" ) -> Valid | AC17: 0 | AD17: =IF(C17<B17,"Invalid Shipping Date","Valid") -> Valid | AE17: =IF(AND(B17<>"",NOT(ISNUMBER(B17))),"Text Not Date","Valid") -> Valid | AF17: =IF(ISNUMBER(B17),"Valid","Invalid") -> Valid | AG17: =IF(ISNUMBER(C17),"Valid","Invalid") -> Valid | AH17: =IF(OR(B17="",ISBLANK(B17)),"Missing","Valid") -> Valid | AI17: =IF(OR(C17="",ISBLANK(C17)),"Missing","Valid") -> Valid | AJ17: FALSE | AK17: FALSE | AL17: FALSE | AM17: FALSE | AN17: FALSE | AO17: FALSE | AP17: FALSE | AQ17: =IF(OR(P17="",ISBLANK(P17)),0,P17) -> 0 | AR17: =N17*O17*(1-AQ17) -> 23794.56 | AS17: =Q17-AR17 -> 0 | AT17: =AR17-R17 -> 8096.09 | AU17: =S17-AT17 -> 0 | AV17: =AT17/AR17 -> 0.34024962 | AW17: =TEXT(B17,"mmmm") -> July | AX17: =YEAR(B17) -> 2024
A18: ORD-2024-10017 | B18: 45420 | C18: 45427 | D18: CUST-6214 | E18: Aarav Sharma | F18: Consumer | G18: South | H18: Telangana | I18: Hyderabad | J18: Office Supplies | K18: Art | L18: Basic Art 204 | M18: First Class | N18: 4 | O18: 3323.51 | P18: 0.25 | Q18: 9970.53 | R18: 5668.17 | S18: 4302.36 | T18: Paid | U18: Completed | V18: =TEXTJOIN("|",TRUE,A18:U18) -> #NAME? | W18: =IFERROR(__xludf.DUMMYFUNCTION("IF(COUNTIF($A:$A,A12)=1, ""Unique"", IF(COUNTUNIQUE(FILTER($V$2:$V$934,$A$2:$A$934=A12))>1, ""Conflicting Duplicate"", ""Exact Duplicate""))"),"Unique") -> Unique | X18: =COUNTIF(V:V,V18)>1 -> TRUE | Y18: =IF(COUNTIF($A:$A,A18)>1,"Duplicate Order ID","Unique") -> Unique | AA18: =IF( OR(AQ18<0, AQ18>1, C18<B18), "Invalid", IF( OR(G18="Unknown", M18="Unknown"), "Warning", "Clean" ) ) -> Clean | AB18: =IF( OR( B18="", C18="", NOT(ISNUMBER(B18)), NOT(ISNUMBER(C18)), C18<B18 ), "Invalid", "Valid" ) -> Valid | AC18: 7 | AD18: =IF(C18<B18,"Invalid Shipping Date","Valid") -> Valid | AE18: =IF(AND(B18<>"",NOT(ISNUMBER(B18))),"Text Not Date","Valid") -> Valid | AF18: =IF(ISNUMBER(B18),"Valid","Invalid") -> Valid | AG18: =IF(ISNUMBER(C18),"Valid","Invalid") -> Valid | AH18: =IF(OR(B18="",ISBLANK(B18)),"Missing","Valid") -> Valid | AI18: =IF(OR(C18="",ISBLANK(C18)),"Missing","Valid") -> Valid | AJ18: FALSE | AK18: FALSE | AL18: FALSE | AM18: FALSE | AN18: FALSE | AO18: FALSE | AP18: FALSE | AQ18: =IF(OR(P18="",ISBLANK(P18)),0,P18) -> 0.25 | AR18: =N18*O18*(1-AQ18) -> 9970.53 | AS18: =Q18-AR18 -> 0 | AT18: =AR18-R18 -> 4302.36 | AU18: =S18-AT18 -> 0 | AV18: =AT18/AR18 -> 0.43150765 | AW18: =TEXT(B18,"mmmm") -> May | AX18: =YEAR(B18) -> 2024
A19: ORD-2024-10018 | B19: 45298 | C19: 45299 | D19: CUST-1626 | E19: Sneha Kapoor | F19: Small Business | G19: North | H19: Rajasthan | I19: Jaipur | J19: Furniture | K19: Furnishings | L19: Basic Furnishings 434 | M19: Same Day | N19: 5 | O19: 1526.78 | P19: 0 | Q19: 7633.9 | R19: 4706.91 | S19: 2926.99 | T19: Paid | U19: Completed | V19: =TEXTJOIN("|",TRUE,A19:U19) -> #NAME? | W19: =IFERROR(__xludf.DUMMYFUNCTION("IF(COUNTIF($A:$A,A13)=1, ""Unique"", IF(COUNTUNIQUE(FILTER($V$2:$V$934,$A$2:$A$934=A13))>1, ""Conflicting Duplicate"", ""Exact Duplicate""))"),"Unique") -> Unique | X19: =COUNTIF(V:V,V19)>1 -> TRUE | Y19: =IF(COUNTIF($A:$A,A19)>1,"Duplicate Order ID","Unique") -> Unique | AA19: =IF( OR(AQ19<0, AQ19>1, C19<B19), "Invalid", IF( OR(G19="Unknown", M19="Unknown"), "Warning", "Clean" ) ) -> Clean | AB19: =IF( OR( B19="", C19="", NOT(ISNUMBER(B19)), NOT(ISNUMBER(C19)), C19<B19 ), "Invalid", "Valid" ) -> Valid | AC19: 1 | AD19: =IF(C19<B19,"Invalid Shipping Date","Valid") -> Valid | AE19: =IF(AND(B19<>"",NOT(ISNUMBER(B19))),"Text Not Date","Valid") -> Valid | AF19: =IF(ISNUMBER(B19),"Valid","Invalid") -> Valid | AG19: =IF(ISNUMBER(C19),"Valid","Invalid") -> Valid | AH19: =IF(OR(B19="",ISBLANK(B19)),"Missing","Valid") -> Valid | AI19: =IF(OR(C19="",ISBLANK(C19)),"Missing","Valid") -> Valid | AJ19: FALSE | AK19: FALSE | AL19: FALSE | AM19: FALSE | AN19: FALSE | AO19: FALSE | AP19: FALSE | AQ19: =IF(OR(P19="",ISBLANK(P19)),0,P19) -> 0 | AR19: =N19*O19*(1-AQ19) -> 7633.9 | AS19: =Q19-AR19 -> 0 | AT19: =AR19-R19 -> 2926.99 | AU19: =S19-AT19 -> 0 | AV19: =AT19/AR19 -> 0.38342001 | AW19: =TEXT(B19,"mmmm") -> January | AX19: =YEAR(B19) -> 2024
A20: ORD-2025-10019 | B20: 45853 | C20: 45855 | D20: CUST-2110 | E20: Aarav Sharma | F20: Home Office | G20: North | H20: Uttar Pradesh | I20: Noida | J20: Technology | K20: Copiers | L20: Eco Copiers 755 | M20: First Class | N20: 2 | O20: 1997.99 | P20: 0 | Q20: 3995.98 | R20: 2633.2 | S20: 1362.78 | T20: Refunded | U20: Cancelled | V20: =TEXTJOIN("|",TRUE,A20:U20) -> #NAME? | W20: =IFERROR(__xludf.DUMMYFUNCTION("IF(COUNTIF($A:$A,A14)=1, ""Unique"", IF(COUNTUNIQUE(FILTER($V$2:$V$934,$A$2:$A$934=A14))>1, ""Conflicting Duplicate"", ""Exact Duplicate""))"),"Unique") -> Unique | X20: =COUNTIF(V:V,V20)>1 -> TRUE | Y20: =IF(COUNTIF($A:$A,A20)>1,"Duplicate Order ID","Unique") -> Unique | AA20: =IF( OR(AQ20<0, AQ20>1, C20<B20), "Invalid", IF( OR(G20="Unknown", M20="Unknown"), "Warning", "Clean" ) ) -> Clean | AB20: =IF( OR( B20="", C20="", NOT(ISNUMBER(B20)), NOT(ISNUMBER(C20)), C20<B20 ), "Invalid", "Valid" ) -> Valid | AC20: 2 | AD20: =IF(C20<B20,"Invalid Shipping Date","Valid") -> Valid | AE20: =IF(AND(B20<>"",NOT(ISNUMBER(B20))),"Text Not Date","Valid") -> Valid | AF20: =IF(ISNUMBER(B20),"Valid","Invalid") -> Valid | AG20: =IF(ISNUMBER(C20),"Valid","Invalid") -> Valid | AH20: =IF(OR(B20="",ISBLANK(B20)),"Missing","Valid") -> Valid | AI20: =IF(OR(C20="",ISBLANK(C20)),"Missing","Valid") -> Valid | AJ20: FALSE | AK20: FALSE | AL20: FALSE | AM20: FALSE | AN20: FALSE | AO20: FALSE | AP20: FALSE | AQ20: =IF(OR(P20="",ISBLANK(P20)),0,P20) -> 0 | AR20: =N20*O20*(1-AQ20) -> 3995.98 | AS20: =Q20-AR20 -> 0 | AT20: =AR20-R20 -> 1362.78 | AU20: =S20-AT20 -> 0 | AV20: =AT20/AR20 -> 0.34103774 | AW20: =TEXT(B20,"mmmm") -> July | AX20: =YEAR(B20) -> 2025
A21: ORD-2024-10020 | B21: 45500 | C21: 45504 | D21: CUST-3186 | E21: Rohan Mehta | F21: Home Office | G21: West | H21: Madhya Pradesh | I21: Indore | J21: Office Supplies | K21: Storage | L21: Prime Storage 121 | M21: Second Class | N21: 3 | O21: 3887.94 | P21: -0.19 | Q21: 9331.06 | R21: 7529.31 | S21: 1801.75 | T21: Paid | U21: Completed | V21: =TEXTJOIN("|",TRUE,A21:U21) -> #NAME? | W21: =IFERROR(__xludf.DUMMYFUNCTION("IF(COUNTIF($A:$A,A15)=1, ""Unique"", IF(COUNTUNIQUE(FILTER($V$2:$V$934,$A$2:$A$934=A15))>1, ""Conflicting Duplicate"", ""Exact Duplicate""))"),"Unique") -> Unique | X21: =COUNTIF(V:V,V21)>1 -> TRUE | Y21: =IF(COUNTIF($A:$A,A21)>1,"Duplicate Order ID","Unique") -> Unique | AA21: =IF( OR(AQ21<0, AQ21>1, C21<B21), "Invalid", IF( OR(G21="Unknown", M21="Unknown"), "Warning", "Clean" ) ) -> Invalid | AB21: =IF( OR( B21="", C21="", NOT(ISNUMBER(B21)), NOT(ISNUMBER(C21)), C21<B21 ), "Invalid", "Valid" ) -> Valid | AC21: 4 | AD21: =IF(C21<B21,"Invalid Shipping Date","Valid") -> Valid | AE21: =IF(AND(B21<>"",NOT(ISNUMBER(B21))),"Text Not Date","Valid") -> Valid | AF21: =IF(ISNUMBER(B21),"Valid","Invalid") -> Valid | AG21: =IF(ISNUMBER(C21),"Valid","Invalid") -> Valid | AH21: =IF(OR(B21="",ISBLANK(B21)),"Missing","Valid") -> Valid | AI21: =IF(OR(C21="",ISBLANK(C21)),"Missing","Valid") -> Valid | AJ21: FALSE | AK21: FALSE | AL21: FALSE | AM21: TRUE | AN21: FALSE | AO21: FALSE | AP21: TRUE | AQ21: =IF(OR(P21="",ISBLANK(P21)),0,P21) -> -0.19 | AR21: =N21*O21*(1-AQ21) -> 13879.946 | AS21: =Q21-AR21 -> -4548.8858 | AT21: =AR21-R21 -> 6350.6358 | AU21: =S21-AT21 -> -4548.8858 | AV21: =AT21/AR21 -> 0.45754039 | AW21: =TEXT(B21,"mmmm") -> July | AX21: =YEAR(B21) -> 2024
A22: ORD-2025-10021 | B22: 45678 | C22: 45680 | D22: CUST-3190 | E22: Aditi Sen | F22: Home Office | G22: East | H22: Bihar | I22: Patna | J22: Technology | K22: Copiers | L22: Elite Copiers 233 | M22: First Class | N22: 5 | O22: 4373.06 | P22: 0.25 | Q22: 16398.98 | R22: 9556.52 | S22: 6842.46 | T22: Paid | U22: Completed | V22: =TEXTJOIN("|",TRUE,A22:U22) -> #NAME? | W22: =IFERROR(__xludf.DUMMYFUNCTION("IF(COUNTIF($A:$A,A16)=1, ""Unique"", IF(COUNTUNIQUE(FILTER($V$2:$V$934,$A$2:$A$934=A16))>1, ""Conflicting Duplicate"", ""Exact Duplicate""))"),"Unique") -> Unique | X22: =COUNTIF(V:V,V22)>1 -> TRUE | Y22: =IF(COUNTIF($A:$A,A22)>1,"Duplicate Order ID","Unique") -> Unique | AA22: =IF( OR(AQ22<0, AQ22>1, C22<B22), "Invalid", IF( OR(G22="Unknown", M22="Unknown"), "Warning", "Clean" ) ) -> Clean | AB22: =IF( OR( B22="", C22="", NOT(ISNUMBER(B22)), NOT(ISNUMBER(C22)), C22<B22 ), "Invalid", "Valid" ) -> Valid | AC22: 2 | AD22: =IF(C22<B22,"Invalid Shipping Date","Valid") -> Valid | AE22: =IF(AND(B22<>"",NOT(ISNUMBER(B22))),"Text Not Date","Valid") -> Valid | AF22: =IF(ISNUMBER(B22),"Valid","Invalid") -> Valid | AG22: =IF(ISNUMBER(C22),"Valid","Invalid") -> Valid | AH22: =IF(OR(B22="",ISBLANK(B22)),"Missing","Valid") -> Valid | AI22: =IF(OR(C22="",ISBLANK(C22)),"Missing","Valid") -> Valid | AJ22: FALSE | AK22: FALSE | AL22: FALSE | AM22: FALSE | AN22: FALSE | AO22: FALSE | AP22: FALSE | AQ22: =IF(OR(P22="",ISBLANK(P22)),0,P22) -> 0.25 | AR22: =N22*O22*(1-AQ22) -> 16398.975 | AS22: =Q22-AR22 -> 0.005 | AT22: =AR22-R22 -> 6842.455 | AU22: =S22-AT22 -> 0.005 | AV22: =AT22/AR22 -> 0.41724894 | AW22: =TEXT(B22,"mmmm") -> January | AX22: =YEAR(B22) -> 2025
A23: ORD-2025-10022 | B23: 45681 | C23: 45687 | D23: CUST-3036 | E23: Sneha Kapoor | F23: Consumer | G23: West | H23: Madhya Pradesh | I23: Indore | J23: Furniture | K23: Furnishings | L23: Eco Furnishings 897 | M23: Second Class | N23: 4 | O23: 697.69 | P23: -0.23 | Q23: 2790.76 | R23: 2037.71 | S23: 753.05 | T23: Paid | U23: Completed | V23: =TEXTJOIN("|",TRUE,A23:U23) -> #NAME? | W23: =IFERROR(__xludf.DUMMYFUNCTION("IF(COUNTIF($A:$A,A17)=1, ""Unique"", IF(COUNTUNIQUE(FILTER($V$2:$V$934,$A$2:$A$934=A17))>1, ""Conflicting Duplicate"", ""Exact Duplicate""))"),"Unique") -> Unique | X23: =COUNTIF(V:V,V23)>1 -> TRUE | Y23: =IF(COUNTIF($A:$A,A23)>1,"Duplicate Order ID","Unique") -> Unique | AA23: =IF( OR(AQ23<0, AQ23>1, C23<B23), "Invalid", IF( OR(G23="Unknown", M23="Unknown"), "Warning", "Clean" ) ) -> Invalid | AB23: =IF( OR( B23="", C23="", NOT(ISNUMBER(B23)), NOT(ISNUMBER(C23)), C23<B23 ), "Invalid", "Valid" ) -> Valid | AC23: 6 | AD23: =IF(C23<B23,"Invalid Shipping Date","Valid") -> Valid | AE23: =IF(AND(B23<>"",NOT(ISNUMBER(B23))),"Text Not Date","Valid") -> Valid | AF23: =IF(ISNUMBER(B23),"Valid","Invalid") -> Valid | AG23: =IF(ISNUMBER(C23),"Valid","Invalid") -> Valid | AH23: =IF(OR(B23="",ISBLANK(B23)),"Missing","Valid") -> Valid | AI23: =IF(OR(C23="",ISBLANK(C23)),"Missing","Valid") -> Valid | AJ23: FALSE | AK23: FALSE | AL23: FALSE | AM23: TRUE | AN23: FALSE | AO23: FALSE | AP23: TRUE | AQ23: =IF(OR(P23="",ISBLANK(P23)),0,P23) -> -0.23 | AR23: =N23*O23*(1-AQ23) -> 3432.6348 | AS23: =Q23-AR23 -> -641.8748 | AT23: =AR23-R23 -> 1394.9248 | AU23: =S23-AT23 -> -641.8748 | AV23: =AT23/AR23 -> 0.40637146 | AW23: =TEXT(B23,"mmmm") -> January | AX23: =YEAR(B23) -> 2025
A24: ORD-2025-10023 | B24: 45676 | C24: 45678 | D24: CUST-3588 | E24: Mira Das | F24: Consumer | G24: South | H24: Telangana | I24: Hyderabad | J24: Office Supplies | K24: Binders | L24: Max Binders 355 | M24: Standard Class | N24: 8 | O24: 1219.34 | P24: 0.15 | Q24: 8291.51 | R24: 6685.03 | S24: 1606.48 | T24: Failed | U24: Returned | V24: =TEXTJOIN("|",TRUE,A24:U24) -> #NAME? | W24: =IFERROR(__xludf.DUMMYFUNCTION("IF(COUNTIF($A:$A,A18)=1, ""Unique"", IF(COUNTUNIQUE(FILTER($V$2:$V$934,$A$2:$A$934=A18))>1, ""Conflicting Duplicate"", ""Exact Duplicate""))"),"Unique") -> Unique | X24: =COUNTIF(V:V,V24)>1 -> TRUE | Y24: =IF(COUNTIF($A:$A,A24)>1,"Duplicate Order ID","Unique") -> Unique | AA24: =IF( OR(AQ24<0, AQ24>1, C24<B24), "Invalid", IF( OR(G24="Unknown", M24="Unknown"), "Warning", "Clean" ) ) -> Clean | AB24: =IF( OR( B24="", C24="", NOT(ISNUMBER(B24)), NOT(ISNUMBER(C24)), C24<B24 ), "Invalid", "Valid" ) -> Valid | AC24: 2 | AD24: =IF(C24<B24,"Invalid Shipping Date","Valid") -> Valid | AE24: =IF(AND(B24<>"",NOT(ISNUMBER(B24))),"Text Not Date","Valid") -> Valid | AF24: =IF(ISNUMBER(B24),"Valid","Invalid") -> Valid | AG24: =IF(ISNUMBER(C24),"Valid","Invalid") -> Valid | AH24: =IF(OR(B24="",ISBLANK(B24)),"Missing","Valid") -> Valid | AI24: =IF(OR(C24="",ISBLANK(C24)),"Missing","Valid") -> Valid | AJ24: FALSE | AK24: FALSE | AL24: FALSE | AM24: FALSE | AN24: FALSE | AO24: FALSE | AP24: FALSE | AQ24: =IF(OR(P24="",ISBLANK(P24)),0,P24) -> 0.15 | AR24: =N24*O24*(1-AQ24) -> 8291.512 | AS24: =Q24-AR24 -> -0.002 | AT24: =AR24-R24 -> 1606.482 | AU24: =S24-AT24 -> -0.002 | AV24: =AT24/AR24 -> 0.19375019 | AW24: =TEXT(B24,"mmmm") -> January | AX24: =YEAR(B24) -> 2025
A25: ORD-2025-10024 | B25: 45898 | C25: 45900 | D25: CUST-7098 | E25: Rahul Verma | F25: Home Office | G25: East | H25: Bihar | I25: Patna | J25: Furniture | K25: Bookcases | L25: Pro Bookcases 394 | M25: First Class | N25: 4 | O25: 1958.01 | P25: 0.2 | Q25: 6265.63 | R25: 4321.86 | S25: 1943.77 | T25: Paid | U25: Completed | V25: =TEXTJOIN("|",TRUE,A25:U25) -> #NAME? | W25: =IFERROR(__xludf.DUMMYFUNCTION("IF(COUNTIF($A:$A,A19)=1, ""Unique"", IF(COUNTUNIQUE(FILTER($V$2:$V$934,$A$2:$A$934=A19))>1, ""Conflicting Duplicate"", ""Exact Duplicate""))"),"Unique") -> Unique | X25: =COUNTIF(V:V,V25)>1 -> TRUE | Y25: =IF(COUNTIF($A:$A,A25)>1,"Duplicate Order ID","Unique") -> Unique | AA25: =IF( OR(AQ25<0, AQ25>1, C25<B25), "Invalid", IF( OR(G25="Unknown", M25="Unknown"), "Warning", "Clean" ) ) -> Clean | AB25: =IF( OR( B25="", C25="", NOT(ISNUMBER(B25)), NOT(ISNUMBER(C25)), C25<B25 ), "Invalid", "Valid" ) -> Valid | AC25: 2 | AD25: =IF(C25<B25,"Invalid Shipping Date","Valid") -> Valid | AE25: =IF(AND(B25<>"",NOT(ISNUMBER(B25))),"Text Not Date","Valid") -> Valid | AF25: =IF(ISNUMBER(B25),"Valid","Invalid") -> Valid | AG25: =IF(ISNUMBER(C25),"Valid","Invalid") -> Valid | AH25: =IF(OR(B25="",ISBLANK(B25)),"Missing","Valid") -> Valid | AI25: =IF(OR(C25="",ISBLANK(C25)),"Missing","Valid") -> Valid | AJ25: FALSE | AK25: FALSE | AL25: FALSE | AM25: FALSE | AN25: FALSE | AO25: FALSE | AP25: FALSE | AQ25: =IF(OR(P25="",ISBLANK(P25)),0,P25) -> 0.2 | AR25: =N25*O25*(1-AQ25) -> 6265.632 | AS25: =Q25-AR25 -> -0.002 | AT25: =AR25-R25 -> 1943.772 | AU25: =S25-AT25 -> -0.002 | AV25: =AT25/AR25 -> 0.3102276 | AW25: =TEXT(B25,"mmmm") -> August | AX25: =YEAR(B25) -> 2025
A26: ORD-2024-10025 | B26: 45355 | C26: 45352 | D26: CUST-1747 | E26: Diya Patel | F26: Consumer | G26: North | H26: Punjab | I26: Ludhiana | J26: Office Supplies | K26: Art | L26: Max Art 215 | M26: Standard Class | N26: 4 | O26: 4492.94 | P26: 0.25 | Q26: 13478.82 | R26: 10937.35 | S26: 2541.47 | T26: Pending | U26: Cancelled | V26: =TEXTJOIN("|",TRUE,A26:U26) -> #NAME? | W26: =IFERROR(__xludf.DUMMYFUNCTION("IF(COUNTIF($A:$A,A20)=1, ""Unique"", IF(COUNTUNIQUE(FILTER($V$2:$V$934,$A$2:$A$934=A20))>1, ""Conflicting Duplicate"", ""Exact Duplicate""))"),"Unique") -> Unique | X26: =COUNTIF(V:V,V26)>1 -> TRUE | Y26: =IF(COUNTIF($A:$A,A26)>1,"Duplicate Order ID","Unique") -> Unique | AA26: =IF( OR(AQ26<0, AQ26>1, C26<B26), "Invalid", IF( OR(G26="Unknown", M26="Unknown"), "Warning", "Clean" ) ) -> Invalid | AB26: =IF( OR( B26="", C26="", NOT(ISNUMBER(B26)), NOT(ISNUMBER(C26)), C26<B26 ), "Invalid", "Valid" ) -> Invalid | AC26: -3 | AD26: =IF(C26<B26,"Invalid Shipping Date","Valid") -> Invalid Shipping Date | AE26: =IF(AND(B26<>"",NOT(ISNUMBER(B26))),"Text Not Date","Valid") -> Valid | AF26: =IF(ISNUMBER(B26),"Valid","Invalid") -> Valid | AG26: =IF(ISNUMBER(C26),"Valid","Invalid") -> Valid | AH26: =IF(OR(B26="",ISBLANK(B26)),"Missing","Valid") -> Valid | AI26: =IF(OR(C26="",ISBLANK(C26)),"Missing","Valid") -> Valid | AJ26: FALSE | AK26: FALSE | AL26: FALSE | AM26: FALSE | AN26: FALSE | AO26: TRUE | AP26: TRUE | AQ26: =IF(OR(P26="",ISBLANK(P26)),0,P26) -> 0.25 | AR26: =N26*O26*(1-AQ26) -> 13478.82 | AS26: =Q26-AR26 -> 0 | AT26: =AR26-R26 -> 2541.47 | AU26: =S26-AT26 -> 0 | AV26: =AT26/AR26 -> 0.18855286 | AW26: =TEXT(B26,"mmmm") -> March | AX26: =YEAR(B26) -> 2024
A27: ORD-2024-10026 | B27: 45576 | C27: 45584 | D27: CUST-1731 | E27: Arjun Bose | F27: Corporate | G27: East | H27: Assam | I27: Guwahati | J27: Technology | K27: Accessories | L27: Classic Accessories 478 | M27: First Class | N27: 2 | O27: 4315.2 | P27: 0.15 | Q27: 7335.84 | R27: 4968.41 | S27: 2367.43 | T27: Paid | U27: Completed | V27: =TEXTJOIN("|",TRUE,A27:U27) -> #NAME? | W27: =IFERROR(__xludf.DUMMYFUNCTION("IF(COUNTIF($A:$A,A21)=1, ""Unique"", IF(COUNTUNIQUE(FILTER($V$2:$V$934,$A$2:$A$934=A21))>1, ""Conflicting Duplicate"", ""Exact Duplicate""))"),"Unique") -> Unique | X27: =COUNTIF(V:V,V27)>1 -> TRUE | Y27: =IF(COUNTIF($A:$A,A27)>1,"Duplicate Order ID","Unique") -> Unique | AA27: =IF( OR(AQ27<0, AQ27>1, C27<B27), "Invalid", IF( OR(G27="Unknown", M27="Unknown"), "Warning", "Clean" ) ) -> Clean | AB27: =IF( OR( B27="", C27="", NOT(ISNUMBER(B27)), NOT(ISNUMBER(C27)), C27<B27 ), "Invalid", "Valid" ) -> Valid | AC27: 8 | AD27: =IF(C27<B27,"Invalid Shipping Date","Valid") -> Valid | AE27: =IF(AND(B27<>"",NOT(ISNUMBER(B27))),"Text Not Date","Valid") -> Valid | AF27: =IF(ISNUMBER(B27),"Valid","Invalid") -> Valid | AG27: =IF(ISNUMBER(C27),"Valid","Invalid") -> Valid | AH27: =IF(OR(B27="",ISBLANK(B27)),"Missing","Valid") -> Valid | AI27: =IF(OR(C27="",ISBLANK(C27)),"Missing","Valid") -> Valid | AJ27: FALSE | AK27: FALSE | AL27: FALSE | AM27: FALSE | AN27: FALSE | AO27: FALSE | AP27: FALSE | AQ27: =IF(OR(P27="",ISBLANK(P27)),0,P27) -> 0.15 | AR27: =N27*O27*(1-AQ27) -> 7335.84 | AS27: =Q27-AR27 -> 0 | AT27: =AR27-R27 -> 2367.43 | AU27: =S27-AT27 -> 0 | AV27: =AT27/AR27 -> 0.32272105 | AW27: =TEXT(B27,"mmmm") -> October | AX27: =YEAR(B27) -> 2024
A28: ORD-2024-10027 | B28: 45619 | C28: 45619 | D28: CUST-4401 | E28: Diya Patel | F28: Corporate | G28: North | H28: Uttar Pradesh | I28: Noida | J28: Technology | K28: Phones | L28: Pro Phones 243 | M28: Standard Class | N28: 4 | O28: 716.13 | P28: 0.1 | Q28: 2578.07 | R28: 1527.55 | S28: 1050.52 | T28: Paid | U28: Returned | V28: =TEXTJOIN("|",TRUE,A28:U28) -> #NAME? | W28: =IFERROR(__xludf.DUMMYFUNCTION("IF(COUNTIF($A:$A,A22)=1, ""Unique"", IF(COUNTUNIQUE(FILTER($V$2:$V$934,$A$2:$A$934=A22))>1, ""Conflicting Duplicate"", ""Exact Duplicate""))"),"Unique") -> Unique | X28: =COUNTIF(V:V,V28)>1 -> TRUE | Y28: =IF(COUNTIF($A:$A,A28)>1,"Duplicate Order ID","Unique") -> Unique | AA28: =IF( OR(AQ28<0, AQ28>1, C28<B28), "Invalid", IF( OR(G28="Unknown", M28="Unknown"), "Warning", "Clean" ) ) -> Clean | AB28: =IF( OR( B28="", C28="", NOT(ISNUMBER(B28)), NOT(ISNUMBER(C28)), C28<B28 ), "Invalid", "Valid" ) -> Valid | AC28: 0 | AD28: =IF(C28<B28,"Invalid Shipping Date","Valid") -> Valid | AE28: =IF(AND(B28<>"",NOT(ISNUMBER(B28))),"Text Not Date","Valid") -> Valid | AF28: =IF(ISNUMBER(B28),"Valid","Invalid") -> Valid | AG28: =IF(ISNUMBER(C28),"Valid","Invalid") -> Valid | AH28: =IF(OR(B28="",ISBLANK(B28)),"Missing","Valid") -> Valid | AI28: =IF(OR(C28="",ISBLANK(C28)),"Missing","Valid") -> Valid | AJ28: FALSE | AK28: FALSE | AL28: FALSE | AM28: FALSE | AN28: FALSE | AO28: FALSE | AP28: FALSE | AQ28: =IF(OR(P28="",ISBLANK(P28)),0,P28) -> 0.1 | AR28: =N28*O28*(1-AQ28) -> 2578.068 | AS28: =Q28-AR28 -> 0.002 | AT28: =AR28-R28 -> 1050.518 | AU28: =S28-AT28 -> 0.002 | AV28: =AT28/AR28 -> 0.40748266 | AW28: =TEXT(B28,"mmmm") -> November | AX28: =YEAR(B28) -> 2024
A29: ORD-2025-10028 | B29: 45929 | C29: 45935 | D29: CUST-9875 | E29: Arjun Bose | F29: Small Business | G29: South | H29: Karnataka | I29: Bengaluru | J29: Office Supplies | K29: Paper | L29: Basic Paper 613 | M29: Second Class | N29: 5 | O29: 1806.51 | P29: 0.25 | Q29: 6774.41 | R29: 4710.36 | S29: 2064.05 | T29: Failed | U29: Returned | V29: =TEXTJOIN("|",TRUE,A29:U29) -> #NAME? | W29: =IFERROR(__xludf.DUMMYFUNCTION("IF(COUNTIF($A:$A,A23)=1, ""Unique"", IF(COUNTUNIQUE(FILTER($V$2:$V$934,$A$2:$A$934=A23))>1, ""Conflicting Duplicate"", ""Exact Duplicate""))"),"Unique") -> Unique | X29: =COUNTIF(V:V,V29)>1 -> TRUE | Y29: =IF(COUNTIF($A:$A,A29)>1,"Duplicate Order ID","Unique") -> Unique | AA29: =IF( OR(AQ29<0, AQ29>1, C29<B29), "Invalid", IF( OR(G29="Unknown", M29="Unknown"), "Warning", "Clean" ) ) -> Clean | AB29: =IF( OR( B29="", C29="", NOT(ISNUMBER(B29)), NOT(ISNUMBER(C29)), C29<B29 ), "Invalid", "Valid" ) -> Valid | AC29: 6 | AD29: =IF(C29<B29,"Invalid Shipping Date","Valid") -> Valid | AE29: =IF(AND(B29<>"",NOT(ISNUMBER(B29))),"Text Not Date","Valid") -> Valid | AF29: =IF(ISNUMBER(B29),"Valid","Invalid") -> Valid | AG29: =IF(ISNUMBER(C29),"Valid","Invalid") -> Valid | AH29: =IF(OR(B29="",ISBLANK(B29)),"Missing","Valid") -> Valid | AI29: =IF(OR(C29="",ISBLANK(C29)),"Missing","Valid") -> Valid | AJ29: FALSE | AK29: FALSE | AL29: FALSE | AM29: FALSE | AN29: FALSE | AO29: FALSE | AP29: FALSE | AQ29: =IF(OR(P29="",ISBLANK(P29)),0,P29) -> 0.25 | AR29: =N29*O29*(1-AQ29) -> 6774.4125 | AS29: =Q29-AR29 -> -0.0025 | AT29: =AR29-R29 -> 2064.0525 | AU29: =S29-AT29 -> -0.0025 | AV29: =AT29/AR29 -> 0.30468362 | AW29: =TEXT(B29,"mmmm") -> September | AX29: =YEAR(B29) -> 2025
A30: ORD-2024-10029 | B30: 45576 | C30: 45583 | D30: CUST-1569 | E30: Ananya Rao | F30: Home Office | G30: West | H30: Gujarat | I30: Ahmedabad | J30: Technology | K30: Phones | L30: Prime Phones 698 | M30: Second Class | N30: 2 | O30: 1942.22 | P30: 0.25 | Q30: 2913.33 | R30: 2122.33 | S30: 791 | T30: Refunded | U30: Cancelled | V30: =TEXTJOIN("|",TRUE,A30:U30) -> #NAME? | W30: =IFERROR(__xludf.DUMMYFUNCTION("IF(COUNTIF($A:$A,A24)=1, ""Unique"", IF(COUNTUNIQUE(FILTER($V$2:$V$934,$A$2:$A$934=A24))>1, ""Conflicting Duplicate"", ""Exact Duplicate""))"),"Unique") -> Unique | X30: =COUNTIF(V:V,V30)>1 -> TRUE | Y30: =IF(COUNTIF($A:$A,A30)>1,"Duplicate Order ID","Unique") -> Unique | AA30: =IF( OR(AQ30<0, AQ30>1, C30<B30), "Invalid", IF( OR(G30="Unknown", M30="Unknown"), "Warning", "Clean" ) ) -> Clean | AB30: =IF( OR( B30="", C30="", NOT(ISNUMBER(B30)), NOT(ISNUMBER(C30)), C30<B30 ), "Invalid", "Valid" ) -> Valid | AC30: 7 | AD30: =IF(C30<B30,"Invalid Shipping Date","Valid") -> Valid | AE30: =IF(AND(B30<>"",NOT(ISNUMBER(B30))),"Text Not Date","Valid") -> Valid | AF30: =IF(ISNUMBER(B30),"Valid","Invalid") -> Valid | AG30: =IF(ISNUMBER(C30),"Valid","Invalid") -> Valid | AH30: =IF(OR(B30="",ISBLANK(B30)),"Missing","Valid") -> Valid | AI30: =IF(OR(C30="",ISBLANK(C30)),"Missing","Valid") -> Valid | AJ30: FALSE | AK30: FALSE | AL30: FALSE | AM30: FALSE | AN30: FALSE | AO30: FALSE | AP30: FALSE | AQ30: =IF(OR(P30="",ISBLANK(P30)),0,P30) -> 0.25 | AR30: =N30*O30*(1-AQ30) -> 2913.33 | AS30: =Q30-AR30 -> 0 | AT30: =AR30-R30 -> 791 | AU30: =S30-AT30 -> 0 | AV30: =AT30/AR30 -> 0.27151061 | AW30: =TEXT(B30,"mmmm") -> October | AX30: =YEAR(B30) -> 2024
A31: ORD-2025-10030 | B31: 45882 | C31: 45882 | D31: CUST-5936 | E31: Rohan Mehta | F31: Home Office | G31: South | H31: Kerala | I31: Kochi | J31: Technology | K31: Phones | L31: Pro Phones 442 | M31: Standard Class | N31: 1 | O31: 256.01 | P31: 0.15 | Q31: 217.61 | R31: 119.77 | S31: 97.84 | T31: Paid | U31: Completed | V31: =TEXTJOIN("|",TRUE,A31:U31) -> #NAME? | W31: =IFERROR(__xludf.DUMMYFUNCTION("IF(COUNTIF($A:$A,A25)=1, ""Unique"", IF(COUNTUNIQUE(FILTER($V$2:$V$934,$A$2:$A$934=A25))>1, ""Conflicting Duplicate"", ""Exact Duplicate""))"),"Unique") -> Unique | X31: =COUNTIF(V:V,V31)>1 -> TRUE | Y31: =IF(COUNTIF($A:$A,A31)>1,"Duplicate Order ID","Unique") -> Unique | AA31: =IF( OR(AQ31<0, AQ31>1, C31<B31), "Invalid", IF( OR(G31="Unknown", M31="Unknown"), "Warning", "Clean" ) ) -> Clean | AB31: =IF( OR( B31="", C31="", NOT(ISNUMBER(B31)), NOT(ISNUMBER(C31)), C31<B31 ), "Invalid", "Valid" ) -> Valid | AC31: 0 | AD31: =IF(C31<B31,"Invalid Shipping Date","Valid") -> Valid | AE31: =IF(AND(B31<>"",NOT(ISNUMBER(B31))),"Text Not Date","Valid") -> Valid | AF31: =IF(ISNUMBER(B31),"Valid","Invalid") -> Valid | AG31: =IF(ISNUMBER(C31),"Valid","Invalid") -> Valid | AH31: =IF(OR(B31="",ISBLANK(B31)),"Missing","Valid") -> Valid | AI31: =IF(OR(C31="",ISBLANK(C31)),"Missing","Valid") -> Valid | AJ31: FALSE | AK31: FALSE | AL31: FALSE | AM31: FALSE | AN31: FALSE | AO31: FALSE | AP31: FALSE | AQ31: =IF(OR(P31="",ISBLANK(P31)),0,P31) -> 0.15 | AR31: =N31*O31*(1-AQ31) -> 217.6085 | AS31: =Q31-AR31 -> 0.0015 | AT31: =AR31-R31 -> 97.8385 | AU31: =S31-AT31 -> 0.0015 | AV31: =AT31/AR31 -> 0.4496079 | AW31: =TEXT(B31,"mmmm") -> August | AX31: =YEAR(B31) -> 2025
A32: ORD-2024-10031 | B32: 45331 | C32: 45334 | D32: CUST-8759 | E32: Ananya Rao | F32: Corporate | G32: West | H32: Goa | I32: Panaji | J32: Office Supplies | K32: Labels | L32: Pro Labels 355 | M32: First Class | N32: 1 | O32: 3421.77 | P32: 0.1 | Q32: 3079.59 | R32: 2001.89 | S32: 1077.7 | T32: Paid | U32: Completed | V32: =TEXTJOIN("|",TRUE,A32:U32) -> #NAME? | W32: =IFERROR(__xludf.DUMMYFUNCTION("IF(COUNTIF($A:$A,A26)=1, ""Unique"", IF(COUNTUNIQUE(FILTER($V$2:$V$934,$A$2:$A$934=A26))>1, ""Conflicting Duplicate"", ""Exact Duplicate""))"),"Unique") -> Unique | X32: =COUNTIF(V:V,V32)>1 -> TRUE | Y32: =IF(COUNTIF($A:$A,A32)>1,"Duplicate Order ID","Unique") -> Unique | AA32: =IF( OR(AQ32<0, AQ32>1, C32<B32), "Invalid", IF( OR(G32="Unknown", M32="Unknown"), "Warning", "Clean" ) ) -> Clean | AB32: =IF( OR( B32="", C32="", NOT(ISNUMBER(B32)), NOT(ISNUMBER(C32)), C32<B32 ), "Invalid", "Valid" ) -> Valid | AC32: 3 | AD32: =IF(C32<B32,"Invalid Shipping Date","Valid") -> Valid | AE32: =IF(AND(B32<>"",NOT(ISNUMBER(B32))),"Text Not Date","Valid") -> Valid | AF32: =IF(ISNUMBER(B32),"Valid","Invalid") -> Valid | AG32: =IF(ISNUMBER(C32),"Valid","Invalid") -> Valid | AH32: =IF(OR(B32="",ISBLANK(B32)),"Missing","Valid") -> Valid | AI32: =IF(OR(C32="",ISBLANK(C32)),"Missing","Valid") -> Valid | AJ32: FALSE | AK32: FALSE | AL32: FALSE | AM32: FALSE | AN32: FALSE | AO32: FALSE | AP32: FALSE | AQ32: =IF(OR(P32="",ISBLANK(P32)),0,P32) -> 0.1 | AR32: =N32*O32*(1-AQ32) -> 3079.593 | AS32: =Q32-AR32 -> -0.003 | AT32: =AR32-R32 -> 1077.703 | AU32: =S32-AT32 -> -0.003 | AV32: =AT32/AR32 -> 0.34994981 | AW32: =TEXT(B32,"mmmm") -> February | AX32: =YEAR(B32) -> 2024
A33: ORD-2025-10032 | B33: 45823 | C33: 45827 | D33: CUST-7867 | E33: Karan Malhotra | F33: Small Business | G33: West | H33: Madhya Pradesh | I33: Indore | J33: Office Supplies | K33: Paper | L33: Pro Paper 959 | M33: Second Class | N33: 9 | O33: 3092.55 | P33: 0 | Q33: 27832.95 | R33: 17769.75 | S33: 10063.2 | T33: Failed | U33: Returned | V33: =TEXTJOIN("|",TRUE,A33:U33) -> #NAME? | W33: =IFERROR(__xludf.DUMMYFUNCTION("IF(COUNTIF($A:$A,A27)=1, ""Unique"", IF(COUNTUNIQUE(FILTER($V$2:$V$934,$A$2:$A$934=A27))>1, ""Conflicting Duplicate"", ""Exact Duplicate""))"),"Unique") -> Unique | X33: =COUNTIF(V:V,V33)>1 -> TRUE | Y33: =IF(COUNTIF($A:$A,A33)>1,"Duplicate Order ID","Unique") -> Unique | AA33: =IF( OR(AQ33<0, AQ33>1, C33<B33), "Invalid", IF( OR(G33="Unknown", M33="Unknown"), "Warning", "Clean" ) ) -> Clean | AB33: =IF( OR( B33="", C33="", NOT(ISNUMBER(B33)), NOT(ISNUMBER(C33)), C33<B33 ), "Invalid", "Valid" ) -> Valid | AC33: 4 | AD33: =IF(C33<B33,"Invalid Shipping Date","Valid") -> Valid | AE33: =IF(AND(B33<>"",NOT(ISNUMBER(B33))),"Text Not Date","Valid") -> Valid | AF33: =IF(ISNUMBER(B33),"Valid","Invalid") -> Valid | AG33: =IF(ISNUMBER(C33),"Valid","Invalid") -> Valid | AH33: =IF(OR(B33="",ISBLANK(B33)),"Missing","Valid") -> Valid | AI33: =IF(OR(C33="",ISBLANK(C33)),"Missing","Valid") -> Valid | AJ33: FALSE | AK33: FALSE | AL33: FALSE | AM33: FALSE | AN33: FALSE | AO33: FALSE | AP33: FALSE | AQ33: =IF(OR(P33="",ISBLANK(P33)),0,P33) -> 0 | AR33: =N33*O33*(1-AQ33) -> 27832.95 | AS33: =Q33-AR33 -> 0 | AT33: =AR33-R33 -> 10063.2 | AU33: =S33-AT33 -> 0 | AV33: =AT33/AR33 -> 0.36155708 | AW33: =TEXT(B33,"mmmm") -> June | AX33: =YEAR(B33) -> 2025
A34: ORD-2024-10033 | B34: 45618 | C34: 45622 | D34: CUST-6509 | E34: Aarav Sharma | F34: Corporate | G34: South | H34: Andhra Pradesh | I34: Vijayawada | J34: Technology | K34: Phones | L34: Basic Phones 242 | M34: Second Class | N34: 3 | O34: 4001.25 | P34: 0 | Q34: 9002.81 | R34: 7529.92 | S34: 1472.89 | T34: Paid | U34: Completed | V34: =TEXTJOIN("|",TRUE,A34:U34) -> #NAME? | W34: =IFERROR(__xludf.DUMMYFUNCTION("IF(COUNTIF($A:$A,A28)=1, ""Unique"", IF(COUNTUNIQUE(FILTER($V$2:$V$934,$A$2:$A$934=A28))>1, ""Conflicting Duplicate"", ""Exact Duplicate""))"),"Unique") -> Unique | X34: =COUNTIF(V:V,V34)>1 -> TRUE | Y34: =IF(COUNTIF($A:$A,A34)>1,"Duplicate Order ID","Unique") -> Unique | AA34: =IF( OR(AQ34<0, AQ34>1, C34<B34), "Invalid", IF( OR(G34="Unknown", M34="Unknown"), "Warning", "Clean" ) ) -> Clean | AB34: =IF( OR( B34="", C34="", NOT(ISNUMBER(B34)), NOT(ISNUMBER(C34)), C34<B34 ), "Invalid", "Valid" ) -> Valid | AC34: 4 | AD34: =IF(C34<B34,"Invalid Shipping Date","Valid") -> Valid | AE34: =IF(AND(B34<>"",NOT(ISNUMBER(B34))),"Text Not Date","Valid") -> Valid | AF34: =IF(ISNUMBER(B34),"Valid","Invalid") -> Valid | AG34: =IF(ISNUMBER(C34),"Valid","Invalid") -> Valid | AH34: =IF(OR(B34="",ISBLANK(B34)),"Missing","Valid") -> Valid | AI34: =IF(OR(C34="",ISBLANK(C34)),"Missing","Valid") -> Valid | AJ34: FALSE | AK34: FALSE | AL34: TRUE | AM34: FALSE | AN34: FALSE | AO34: FALSE | AP34: TRUE | AQ34: =IF(OR(P34="",ISBLANK(P34)),0,P34) -> 0 | AR34: =N34*O34*(1-AQ34) -> 12003.75 | AS34: =Q34-AR34 -> -3000.94 | AT34: =AR34-R34 -> 4473.83 | AU34: =S34-AT34 -> -3000.94 | AV34: =AT34/AR34 -> 0.3727027 | AW34: =TEXT(B34,"mmmm") -> November | AX34: =YEAR(B34) -> 2024
A35: ORD-2024-10034 | B35: 45495 | C35: 45500 | D35: CUST-6660 | E35: Priya Menon | F35: Home Office | G35: West | H35: Goa | I35: Panaji | J35: Furniture | K35: Tables | L35: Max Tables 836 | M35: Same Day | N35: 7 | O35: 492.41 | P35: 0.25 | Q35: 2585.15 | R35: 2070.73 | S35: 514.42 | T35: Paid | U35: Completed | V35: =TEXTJOIN("|",TRUE,A35:U35) -> #NAME? | W35: =IFERROR(__xludf.DUMMYFUNCTION("IF(COUNTIF($A:$A,A29)=1, ""Unique"", IF(COUNTUNIQUE(FILTER($V$2:$V$934,$A$2:$A$934=A29))>1, ""Conflicting Duplicate"", ""Exact Duplicate""))"),"Unique") -> Unique | X35: =COUNTIF(V:V,V35)>1 -> TRUE | Y35: =IF(COUNTIF($A:$A,A35)>1,"Duplicate Order ID","Unique") -> Unique | AA35: =IF( OR(AQ35<0, AQ35>1, C35<B35), "Invalid", IF( OR(G35="Unknown", M35="Unknown"), "Warning", "Clean" ) ) -> Clean | AB35: =IF( OR( B35="", C35="", NOT(ISNUMBER(B35)), NOT(ISNUMBER(C35)), C35<B35 ), "Invalid", "Valid" ) -> Valid | AC35: 5 | AD35: =IF(C35<B35,"Invalid Shipping Date","Valid") -> Valid | AE35: =IF(AND(B35<>"",NOT(ISNUMBER(B35))),"Text Not Date","Valid") -> Valid | AF35: =IF(ISNUMBER(B35),"Valid","Invalid") -> Valid | AG35: =IF(ISNUMBER(C35),"Valid","Invalid") -> Valid | AH35: =IF(OR(B35="",ISBLANK(B35)),"Missing","Valid") -> Valid | AI35: =IF(OR(C35="",ISBLANK(C35)),"Missing","Valid") -> Valid | AJ35: FALSE | AK35: FALSE | AL35: FALSE | AM35: FALSE | AN35: FALSE | AO35: FALSE | AP35: FALSE | AQ35: =IF(OR(P35="",ISBLANK(P35)),0,P35) -> 0.25 | AR35: =N35*O35*(1-AQ35) -> 2585.1525 | AS35: =Q35-AR35 -> -0.0025 | AT35: =AR35-R35 -> 514.4225 | AU35: =S35-AT35 -> -0.0025 | AV35: =AT35/AR35 -> 0.19899116 | AW35: =TEXT(B35,"mmmm") -> July | AX35: =YEAR(B35) -> 2024
A36: ORD-2025-10035 | B36: 45688 | C36: 45693 | D36: CUST-2392 | E36: Priya Menon | F36: Home Office | G36: East | H36: West Bengal | I36: Kolkata | J36: Furniture | K36: Chairs | L36: Elite Chairs 862 | M36: Unknown | N36: 2 | O36: 4159.69 | P36: 0.2 | Q36: 6655.5 | R36: 4340.21 | S36: 2607.32 | T36: Paid | U36: Completed | V36: =TEXTJOIN("|",TRUE,A36:U36) -> #NAME? | W36: =IFERROR(__xludf.DUMMYFUNCTION("IF(COUNTIF($A:$A,A30)=1, ""Unique"", IF(COUNTUNIQUE(FILTER($V$2:$V$934,$A$2:$A$934=A30))>1, ""Conflicting Duplicate"", ""Exact Duplicate""))"),"Unique") -> Unique | X36: =COUNTIF(V:V,V36)>1 -> TRUE | Y36: =IF(COUNTIF($A:$A,A36)>1,"Duplicate Order ID","Unique") -> Unique | AA36: =IF( OR(AQ36<0, AQ36>1, C36<B36), "Invalid", IF( OR(G36="Unknown", M36="Unknown"), "Warning", "Clean" ) ) -> Warning | AB36: =IF( OR( B36="", C36="", NOT(ISNUMBER(B36)), NOT(ISNUMBER(C36)), C36<B36 ), "Invalid", "Valid" ) -> Valid | AC36: 5 | AD36: =IF(C36<B36,"Invalid Shipping Date","Valid") -> Valid | AE36: =IF(AND(B36<>"",NOT(ISNUMBER(B36))),"Text Not Date","Valid") -> Valid | AF36: =IF(ISNUMBER(B36),"Valid","Invalid") -> Valid | AG36: =IF(ISNUMBER(C36),"Valid","Invalid") -> Valid | AH36: =IF(OR(B36="",ISBLANK(B36)),"Missing","Valid") -> Valid | AI36: =IF(OR(C36="",ISBLANK(C36)),"Missing","Valid") -> Valid | AJ36: FALSE | AK36: TRUE | AL36: FALSE | AM36: FALSE | AN36: FALSE | AO36: FALSE | AP36: TRUE | AQ36: =IF(OR(P36="",ISBLANK(P36)),0,P36) -> 0.2 | AR36: =N36*O36*(1-AQ36) -> 6655.504 | AS36: =Q36-AR36 -> -0.004 | AT36: =AR36-R36 -> 2315.294 | AU36: =S36-AT36 -> 292.026 | AV36: =AT36/AR36 -> 0.34787658 | AW36: =TEXT(B36,"mmmm") -> January | AX36: =YEAR(B36) -> 2025
A37: ORD-2024-10036 | B37: 45441 | C37: 45441 | D37: CUST-1611 | E37: Sneha Kapoor | F37: Small Business | G37: West | H37: Gujarat | I37: Ahmedabad | J37: Furniture | K37: Bookcases | L37: Prime Bookcases 414 | M37: Second Class | N37: 8 | O37: 2507.12 | P37: 0.05 | Q37: 19054.11 | R37: 15313.83 | S37: 3740.28 | T37: Pending | U37: Returned | V37: =TEXTJOIN("|",TRUE,A37:U37) -> #NAME? | W37: =IFERROR(__xludf.DUMMYFUNCTION("IF(COUNTIF($A:$A,A31)=1, ""Unique"", IF(COUNTUNIQUE(FILTER($V$2:$V$934,$A$2:$A$934=A31))>1, ""Conflicting Duplicate"", ""Exact Duplicate""))"),"Unique") -> Unique | X37: =COUNTIF(V:V,V37)>1 -> TRUE | Y37: =IF(COUNTIF($A:$A,A37)>1,"Duplicate Order ID","Unique") -> Unique | AA37: =IF( OR(AQ37<0, AQ37>1, C37<B37), "Invalid", IF( OR(G37="Unknown", M37="Unknown"), "Warning", "Clean" ) ) -> Clean | AB37: =IF( OR( B37="", C37="", NOT(ISNUMBER(B37)), NOT(ISNUMBER(C37)), C37<B37 ), "Invalid", "Valid" ) -> Valid | AC37: 0 | AD37: =IF(C37<B37,"Invalid Shipping Date","Valid") -> Valid | AE37: =IF(AND(B37<>"",NOT(ISNUMBER(B37))),"Text Not Date","Valid") -> Valid | AF37: =IF(ISNUMBER(B37),"Valid","Invalid") -> Valid | AG37: =IF(ISNUMBER(C37),"Valid","Invalid") -> Valid | AH37: =IF(OR(B37="",ISBLANK(B37)),"Missing","Valid") -> Valid | AI37: =IF(OR(C37="",ISBLANK(C37)),"Missing","Valid") -> Valid | AJ37: FALSE | AK37: FALSE | AL37: FALSE | AM37: FALSE | AN37: FALSE | AO37: FALSE | AP37: FALSE | AQ37: =IF(OR(P37="",ISBLANK(P37)),0,P37) -> 0.05 | AR37: =N37*O37*(1-AQ37) -> 19054.112 | AS37: =Q37-AR37 -> -0.002 | AT37: =AR37-R37 -> 3740.282 | AU37: =S37-AT37 -> -0.002 | AV37: =AT37/AR37 -> 0.19629789 | AW37: =TEXT(B37,"mmmm") -> May | AX37: =YEAR(B37) -> 2024
